Workbook
Name Slicer_diebetes: #N/A
Name Slicer_Weight_Status: #N/A

Sheet Customer Names
A1: Customer ID | B1: name | F1: TITLE | G1: NAME | H1: LAST NAME
A2: Id1 | B2: Hawks, Ms. Kelly | F2: Ms. | G2: Kelly | H2: Hawks
A3: Id2 | B3: Lehner, Mr. Matthew D | F3: Mr. | G3: Matthew D | H3: Lehner
A4: Id3 | B4: Lu, Mr. Phil | F4: Mr. | G4: Phil | H4: Lu
A5: Id4 | B5: Osborne, Ms. Kelsey | F5: Ms. | G5: Kelsey | H5: Osborne
A6: Id5 | B6: Kadala, Ms. Kristyn | F6: Ms. | G6: Kristyn | H6: Kadala
A7: Id6 | B7: Baker, Mr. Russell B. | F7: Mr. | G7: Russell B. | H7: Baker
A8: Id7 | B8: Macpherson, Mr. Scott | F8: Mr. | G8: Scott | H8: Macpherson
A9: Id8 | B9: Hallman, Mr. Stephen | F9: Mr. | G9: Stephen | H9: Hallman
A10: Id9 | B10: Moran, Mr. Patrick R. | F10: Mr. | G10: Patrick R. | H10: Moran
A11: Id10 | B11: Benner, Ms. Brooke N. | F11: Ms. | G11: Brooke N. | H11: Benner
A12: Id11 | B12: Fierro Vargas, Ms. Paola Andrea | F12: Ms. | G12: Paola Andrea | H12: Fierro Vargas
... A2336: Id2335 | B2336: German, Mr. Aaron K | F2336: Mr. | G2336: Aaron K | H2336: German

Sheet Medical Examinations
A1: Customer ID | B1: BMI | C1: HBA1C | D1: Heart Issues | E1: Any Transplants | F1: Cancer history | G1: NumberOfMajorSurgeries | H1: smoker | I1: SMOKER 1 | J1: Number of Major Surgeries | K1: Smoker2 | L1: Heart Issue | M1: Weight Status | N1: diebetes
A2: Id1 | B2: 47.41 | C2: 7.47 | D2: No | E2: No | F2: No | G2: No major surgery | H2: yes | I2: =IF(Table4[[#This Row],[smoker]]="?","NO",Table4[[#This Row],[smoker]]) -> yes | J2: 0 | K2: =UPPER(Table4[[#This Row],[SMOKER 1]]) -> YES | L2: =UPPER(Table4[[#This Row],[Heart Issues]]) -> NO | M2: =IF(Table4[[#This Row],[BMI]]<18.5,"underweight",IF(Table4[[#This Row],[BMI]]< 24.9,"normal weight",IF(Table4[[#This Row],[BMI]]<29.9,"over weight","obesity"))) -> obesity | N2: =IF(Table4[[#This Row],[HBA1C]]<5.7,"normal",IF(Table4[[#This Row],[HBA1C]]< 6.4,"prediabetes","diabetes")) -> diabetes
A3: Id2 | B3: 30.36 | C3: 5.77 | D3: No | E3: No | F3: No | G3: No major surgery | H3: yes | I3: =IF(Table4[[#This Row],[smoker]]="?","NO",Table4[[#This Row],[smoker]]) -> yes | J3: 0 | K3: =UPPER(Table4[[#This Row],[SMOKER 1]]) -> YES | L3: =UPPER(Table4[[#This Row],[Heart Issues]]) -> NO | M3: =IF(Table4[[#This Row],[BMI]]<18.5,"underweight",IF(Table4[[#This Row],[BMI]]< 24.9,"normal weight",IF(Table4[[#This Row],[BMI]]<29.9,"over weight","obesity"))) -> obesity | N3: =IF(Table4[[#This Row],[HBA1C]]<5.7,"normal",IF(Table4[[#This Row],[HBA1C]]< 6.4,"prediabetes","diabetes")) -> prediabetes
A4: Id3 | B4: 34.485 | C4: 11.87 | D4: yes | E4: No | F4: No | G4: 2 | H4: yes | I4: =IF(Table4[[#This Row],[smoker]]="?","NO",Table4[[#This Row],[smoker]]) -> yes | J4: 2 | K4: =UPPER(Table4[[#This Row],[SMOKER 1]]) -> YES | L4: =UPPER(Table4[[#This Row],[Heart Issues]]) -> YES | M4: =IF(Table4[[#This Row],[BMI]]<18.5,"underweight",IF(Table4[[#This Row],[BMI]]< 24.9,"normal weight",IF(Table4[[#This Row],[BMI]]<29.9,"over weight","obesity"))) -> obesity | N4: =IF(Table4[[#This Row],[HBA1C]]<5.7,"normal",IF(Table4[[#This Row],[HBA1C]]< 6.4,"prediabetes","diabetes")) -> diabetes
A5: Id4 | B5: 38.095 | C5: 6.05 | D5: No | E5: No | F5: No | G5: No major surgery | H5: yes | I5: =IF(Table4[[#This Row],[smoker]]="?","NO",Table4[[#This Row],[smoker]]) -> yes | J5: 0 | K5: =UPPER(Table4[[#This Row],[SMOKER 1]]) -> YES | L5: =UPPER(Table4[[#This Row],[Heart Issues]]) -> NO | M5: =IF(Table4[[#This Row],[BMI]]<18.5,"underweight",IF(Table4[[#This Row],[BMI]]< 24.9,"normal weight",IF(Table4[[#This Row],[BMI]]<29.9,"over weight","obesity"))) -> obesity | N5: =IF(Table4[[#This Row],[HBA1C]]<5.7,"normal",IF(Table4[[#This Row],[HBA1C]]< 6.4,"prediabetes","diabetes")) -> prediabetes | P5: COUNT OF MISSING VALUES
A6: Id5 | B6: 35.53 | C6: 5.45 | D6: No | E6: No | F6: No | G6: No major surgery | H6: yes | I6: =IF(Table4[[#This Row],[smoker]]="?","NO",Table4[[#This Row],[smoker]]) -> yes | J6: 0 | K6: =UPPER(Table4[[#This Row],[SMOKER 1]]) -> YES | L6: =UPPER(Table4[[#This Row],[Heart Issues]]) -> NO | M6: =IF(Table4[[#This Row],[BMI]]<18.5,"underweight",IF(Table4[[#This Row],[BMI]]< 24.9,"normal weight",IF(Table4[[#This Row],[BMI]]<29.9,"over weight","obesity"))) -> obesity | N6: =IF(Table4[[#This Row],[HBA1C]]<5.7,"normal",IF(Table4[[#This Row],[HBA1C]]< 6.4,"prediabetes","diabetes")) -> normal | P6: Column1 | Q6: Column2
A7: Id6 | B7: 32.8 | C7: 6.59 | D7: No | E7: No | F7: No | G7: No major surgery | H7: yes | I7: =IF(Table4[[#This Row],[smoker]]="?","NO",Table4[[#This Row],[smoker]]) -> yes | J7: 0 | K7: =UPPER(Table4[[#This Row],[SMOKER 1]]) -> YES | L7: =UPPER(Table4[[#This Row],[Heart Issues]]) -> NO | M7: =IF(Table4[[#This Row],[BMI]]<18.5,"underweight",IF(Table4[[#This Row],[BMI]]< 24.9,"normal weight",IF(Table4[[#This Row],[BMI]]<29.9,"over weight","obesity"))) -> obesity | N7: =IF(Table4[[#This Row],[HBA1C]]<5.7,"normal",IF(Table4[[#This Row],[HBA1C]]< 6.4,"prediabetes","diabetes")) -> diabetes | P7: Customer ID | Q7: =COUNTIF(A2:A2336,"?") -> 0
A8: Id7 | B8: 36.4 | C8: 6.07 | D8: No | E8: No | F8: No | G8: No major surgery | H8: yes | I8: =IF(Table4[[#This Row],[smoker]]="?","NO",Table4[[#This Row],[smoker]]) -> yes | J8: 0 | K8: =UPPER(Table4[[#This Row],[SMOKER 1]]) -> YES | L8: =UPPER(Table4[[#This Row],[Heart Issues]]) -> NO | M8: =IF(Table4[[#This Row],[BMI]]<18.5,"underweight",IF(Table4[[#This Row],[BMI]]< 24.9,"normal weight",IF(Table4[[#This Row],[BMI]]<29.9,"over weight","obesity"))) -> obesity | N8: =IF(Table4[[#This Row],[HBA1C]]<5.7,"normal",IF(Table4[[#This Row],[HBA1C]]< 6.4,"prediabetes","diabetes")) -> prediabetes | P8: BMI | Q8: =COUNTIF(B2:B2336,"?") -> 0
A9: Id8 | B9: 36.96 | C9: 7.93 | D9: No | E9: No | F9: No | G9: 3 | H9: yes | I9: =IF(Table4[[#This Row],[smoker]]="?","NO",Table4[[#This Row],[smoker]]) -> yes | J9: 3 | K9: =UPPER(Table4[[#This Row],[SMOKER 1]]) -> YES | L9: =UPPER(Table4[[#This Row],[Heart Issues]]) -> NO | M9: =IF(Table4[[#This Row],[BMI]]<18.5,"underweight",IF(Table4[[#This Row],[BMI]]< 24.9,"normal weight",IF(Table4[[#This Row],[BMI]]<29.9,"over weight","obesity"))) -> obesity | N9: =IF(Table4[[#This Row],[HBA1C]]<5.7,"normal",IF(Table4[[#This Row],[HBA1C]]< 6.4,"prediabetes","diabetes")) -> diabetes | P9: HBA1C | Q9: =COUNTIF(D2:D2336,"?") -> 0
A10: Id9 | B10: 41.14 | C10: 9.58 | D10: yes | E10: No | F10: Yes | G10: 1 | H10: yes | I10: =IF(Table4[[#This Row],[smoker]]="?","NO",Table4[[#This Row],[smoker]]) -> yes | J10: 1 | K10: =UPPER(Table4[[#This Row],[SMOKER 1]]) -> YES | L10: =UPPER(Table4[[#This Row],[Heart Issues]]) -> YES | M10: =IF(Table4[[#This Row],[BMI]]<18.5,"underweight",IF(Table4[[#This Row],[BMI]]< 24.9,"normal weight",IF(Table4[[#This Row],[BMI]]<29.9,"over weight","obesity"))) -> obesity | N10: =IF(Table4[[#This Row],[HBA1C]]<5.7,"normal",IF(Table4[[#This Row],[HBA1C]]< 6.4,"prediabetes","diabetes")) -> diabetes | P10: Heart Issues | Q10: =COUNTIF(E2:E2336,"?") -> 0
A11: Id10 | B11: 38.06 | C11: 10.79 | D11: No | E11: No | F11: No | G11: No major surgery | H11: yes | I11: =IF(Table4[[#This Row],[smoker]]="?","NO",Table4[[#This Row],[smoker]]) -> yes | J11: 0 | K11: =UPPER(Table4[[#This Row],[SMOKER 1]]) -> YES | L11: =UPPER(Table4[[#This Row],[Heart Issues]]) -> NO | M11: =IF(Table4[[#This Row],[BMI]]<18.5,"underweight",IF(Table4[[#This Row],[BMI]]< 24.9,"normal weight",IF(Table4[[#This Row],[BMI]]<29.9,"over weight","obesity"))) -> obesity | N11: =IF(Table4[[#This Row],[HBA1C]]<5.7,"normal",IF(Table4[[#This Row],[HBA1C]]< 6.4,"prediabetes","diabetes")) -> diabetes | P11: Any Transplants | Q11: =COUNTIF(D2:D2336,"?") -> 0
A12: Id11 | B12: 37.7 | C12: 5.96 | D12: yes | E12: No | F12: No | G12: 2 | H12: yes | I12: =IF(Table4[[#This Row],[smoker]]="?","NO",Table4[[#This Row],[smoker]]) -> yes | J12: 2 | K12: =UPPER(Table4[[#This Row],[SMOKER 1]]) -> YES | L12: =UPPER(Table4[[#This Row],[Heart Issues]]) -> YES | M12: =IF(Table4[[#This Row],[BMI]]<18.5,"underweight",IF(Table4[[#This Row],[BMI]]< 24.9,"normal weight",IF(Table4[[#This Row],[BMI]]<29.9,"over weight","obesity"))) -> obesity | N12: =IF(Table4[[#This Row],[HBA1C]]<5.7,"normal",IF(Table4[[#This Row],[HBA1C]]< 6.4,"prediabetes","diabetes")) -> prediabetes | P12: Cancer history | Q12: =COUNTIF(F2:F2336,"?") -> 0
A13: Id12 | B13: 42.13 | C13: 11.9 | D13: No | E13: No | F13: No | G13: No major surgery | H13: yes | I13: =IF(Table4[[#This Row],[smoker]]="?","NO",Table4[[#This Row],[smoker]]) -> yes | J13: 0 | K13: =UPPER(Table4[[#This Row],[SMOKER 1]]) -> YES | L13: =UPPER(Table4[[#This Row],[Heart Issues]]) -> NO | M13: =IF(Table4[[#This Row],[BMI]]<18.5,"underweight",IF(Table4[[#This Row],[BMI]]< 24.9,"normal weight",IF(Table4[[#This Row],[BMI]]<29.9,"over weight","obesity"))) -> obesity | N13: =IF(Table4[[#This Row],[HBA1C]]<5.7,"normal",IF(Table4[[#This Row],[HBA1C]]< 6.4,"prediabetes","diabetes")) -> diabetes | P13: NumberOfMajorSurgeries | Q13: =COUNTIF(G2:G2336,"?") -> 0
A14: Id13 | B14: 40.92 | C14: 8.41 | D14: No | E14: No | F14: No | G14: No major surgery | H14: yes | I14: =IF(Table4[[#This Row],[smoker]]="?","NO",Table4[[#This Row],[smoker]]) -> yes | J14: 0 | K14: =UPPER(Table4[[#This Row],[SMOKER 1]]) -> YES | L14: =UPPER(Table4[[#This Row],[Heart Issues]]) -> NO | M14: =IF(Table4[[#This Row],[BMI]]<18.5,"underweight",IF(Table4[[#This Row],[BMI]]< 24.9,"normal weight",IF(Table4[[#This Row],[BMI]]<29.9,"over weight","obesity"))) -> obesity | N14: =IF(Table4[[#This Row],[HBA1C]]<5.7,"normal",IF(Table4[[#This Row],[HBA1C]]< 6.4,"prediabetes","diabetes")) -> diabetes | P14: smoker | Q14: =COUNTIF(H2:H2336,"?") -> 2
A15: Id14 | B15: 40.565 | C15: 7.02 | D15: No | E15: No | F15: No | G15: No major surgery | H15: yes | I15: =IF(Table4[[#This Row],[smoker]]="?","NO",Table4[[#This Row],[smoker]]) -> yes | J15: 0 | K15: =UPPER(Table4[[#This Row],[SMOKER 1]]) -> YES | L15: =UPPER(Table4[[#This Row],[Heart Issues]]) -> NO | M15: =IF(Table4[[#This Row],[BMI]]<18.5,"underweight",IF(Table4[[#This Row],[BMI]]< 24.9,"normal weight",IF(Table4[[#This Row],[BMI]]<29.9,"over weight","obesity"))) -> obesity | N15: =IF(Table4[[#This Row],[HBA1C]]<5.7,"normal",IF(Table4[[#This Row],[HBA1C]]< 6.4,"prediabetes","diabetes")) -> diabetes
A16: Id15 | B16: 36.385 | C16: 7.59 | D16: yes | E16: No | F16: No | G16: 2 | H16: yes | I16: =IF(Table4[[#This Row],[smoker]]="?","NO",Table4[[#This Row],[smoker]]) -> yes | J16: 2 | K16: =UPPER(Table4[[#This Row],[SMOKER 1]]) -> YES | L16: =UPPER(Table4[[#This Row],[Heart Issues]]) -> YES | M16: =IF(Table4[[#This Row],[BMI]]<18.5,"underweight",IF(Table4[[#This Row],[BMI]]< 24.9,"normal weight",IF(Table4[[#This Row],[BMI]]<29.9,"over weight","obesity"))) -> obesity | N16: =IF(Table4[[#This Row],[HBA1C]]<5.7,"normal",IF(Table4[[#This Row],[HBA1C]]< 6.4,"prediabetes","diabetes")) -> diabetes
A17: Id16 | B17: 39.9 | C17: 11.32 | D17: No | E17: No | F17: No | G17: No major surgery | H17: yes | I17: =IF(Table4[[#This Row],[smoker]]="?","NO",Table4[[#This Row],[smoker]]) -> yes | J17: 0 | K17: =UPPER(Table4[[#This Row],[SMOKER 1]]) -> YES | L17: =UPPER(Table4[[#This Row],[Heart Issues]]) -> NO | M17: =IF(Table4[[#This Row],[BMI]]<18.5,"underweight",IF(Table4[[#This Row],[BMI]]< 24.9,"normal weight",IF(Table4[[#This Row],[BMI]]<29.9,"over weight","obesity"))) -> obesity | N17: =IF(Table4[[#This Row],[HBA1C]]<5.7,"normal",IF(Table4[[#This Row],[HBA1C]]< 6.4,"prediabetes","diabetes")) -> diabetes
A18: Id17 | B18: 33.8 | C18: 7.67 | D18: No | E18: No | F18: No | G18: 3 | H18: yes | I18: =IF(Table4[[#This Row],[smoker]]="?","NO",Table4[[#This Row],[smoker]]) -> yes | J18: 3 | K18: =UPPER(Table4[[#This Row],[SMOKER 1]]) -> YES | L18: =UPPER(Table4[[#This Row],[Heart Issues]]) -> NO | M18: =IF(Table4[[#This Row],[BMI]]<18.5,"underweight",IF(Table4[[#This Row],[BMI]]< 24.9,"normal weight",IF(Table4[[#This Row],[BMI]]<29.9,"over weight","obesity"))) -> obesity | N18: =IF(Table4[[#This Row],[HBA1C]]<5.7,"normal",IF(Table4[[#This Row],[HBA1C]]< 6.4,"prediabetes","diabetes")) -> diabetes
A19: Id18 | B19: 36.765 | C19: 7.29 | D19: yes | E19: No | F19: Yes | G19: 1 | H19: yes | I19: =IF(Table4[[#This Row],[smoker]]="?","NO",Table4[[#This Row],[smoker]]) -> yes | J19: 1 | K19: =UPPER(Table4[[#This Row],[SMOKER 1]]) -> YES | L19: =UPPER(Table4[[#This Row],[Heart Issues]]) -> YES | M19: =IF(Table4[[#This Row],[BMI]]<18.5,"underweight",IF(Table4[[#This Row],[BMI]]< 24.9,"normal weight",IF(Table4[[#This Row],[BMI]]<29.9,"over weight","obesity"))) -> obesity | N19: =IF(Table4[[#This Row],[HBA1C]]<5.7,"normal",IF(Table4[[#This Row],[HBA1C]]< 6.4,"prediabetes","diabetes")) -> diabetes | P19: Count of most occuring in Somker
A20: Id19 | B20: 36.955 | C20: 4.72 | D20: yes | E20: No | F20: No | G20: 1 | H20: yes | I20: =IF(Table4[[#This Row],[smoker]]="?","NO",Table4[[#This Row],[smoker]]) -> yes | J20: 1 | K20: =UPPER(Table4[[#This Row],[SMOKER 1]]) -> YES | L20: =UPPER(Table4[[#This Row],[Heart Issues]]) -> YES | M20: =IF(Table4[[#This Row],[BMI]]<18.5,"underweight",IF(Table4[[#This Row],[BMI]]< 24.9,"normal weight",IF(Table4[[#This Row],[BMI]]<29.9,"over weight","obesity"))) -> obesity | N20: =IF(Table4[[#This Row],[HBA1C]]<5.7,"normal",IF(Table4[[#This Row],[HBA1C]]< 6.4,"prediabetes","diabetes")) -> normal | P20: Row Labels | Q20: Count of smoker
A21: Id20 | B21: 42.9 | C21: 11.41 | D21: No | E21: No | F21: No | G21: No major surgery | H21: yes | I21: =IF(Table4[[#This Row],[smoker]]="?","NO",Table4[[#This Row],[smoker]]) -> yes | J21: 0 | K21: =UPPER(Table4[[#This Row],[SMOKER 1]]) -> YES | L21: =UPPER(Table4[[#This Row],[Heart Issues]]) -> NO | M21: =IF(Table4[[#This Row],[BMI]]<18.5,"underweight",IF(Table4[[#This Row],[BMI]]< 24.9,"normal weight",IF(Table4[[#This Row],[BMI]]<29.9,"over weight","obesity"))) -> obesity | N21: =IF(Table4[[#This Row],[HBA1C]]<5.7,"normal",IF(Table4[[#This Row],[HBA1C]]< 6.4,"prediabetes","diabetes")) -> diabetes | P21: ? | Q21: 2
A22: Id21 | B22: 36.3 | C22: 11.5 | D22: yes | E22: No | F22: No | G22: 2 | H22: yes | I22: =IF(Table4[[#This Row],[smoker]]="?","NO",Table4[[#This Row],[smoker]]) -> yes | J22: 2 | K22: =UPPER(Table4[[#This Row],[SMOKER 1]]) -> YES | L22: =UPPER(Table4[[#This Row],[Heart Issues]]) -> YES | M22: =IF(Table4[[#This Row],[BMI]]<18.5,"underweight",IF(Table4[[#This Row],[BMI]]< 24.9,"normal weight",IF(Table4[[#This Row],[BMI]]<29.9,"over weight","obesity"))) -> obesity | N22: =IF(Table4[[#This Row],[HBA1C]]<5.7,"normal",IF(Table4[[#This Row],[HBA1C]]< 6.4,"prediabetes","diabetes")) -> diabetes | P22: No | Q22: 1845
A23: Id22 | B23: 32.2 | C23: 6.22 | D23: yes | E23: No | F23: No | G23: 2 | H23: yes | I23: =IF(Table4[[#This Row],[smoker]]="?","NO",Table4[[#This Row],[smoker]]) -> yes | J23: 2 | K23: =UPPER(Table4[[#This Row],[SMOKER 1]]) -> YES | L23: =UPPER(Table4[[#This Row],[Heart Issues]]) -> YES | M23: =IF(Table4[[#This Row],[BMI]]<18.5,"underweight",IF(Table4[[#This Row],[BMI]]< 24.9,"normal weight",IF(Table4[[#This Row],[BMI]]<29.9,"over weight","obesity"))) -> obesity | N23: =IF(Table4[[#This Row],[HBA1C]]<5.7,"normal",IF(Table4[[#This Row],[HBA1C]]< 6.4,"prediabetes","diabetes")) -> prediabetes | P23: yes | Q23: 488
A24: Id23 | B24: 31.3 | C24: 11.38 | D24: No | E24: No | F24: No | G24: 3 | H24: yes | I24: =IF(Table4[[#This Row],[smoker]]="?","NO",Table4[[#This Row],[smoker]]) -> yes | J24: 3 | K24: =UPPER(Table4[[#This Row],[SMOKER 1]]) -> YES | L24: =UPPER(Table4[[#This Row],[Heart Issues]]) -> NO | M24: =IF(Table4[[#This Row],[BMI]]<18.5,"underweight",IF(Table4[[#This Row],[BMI]]< 24.9,"normal weight",IF(Table4[[#This Row],[BMI]]<29.9,"over weight","obesity"))) -> obesity | N24: =IF(Table4[[#This Row],[HBA1C]]<5.7,"normal",IF(Table4[[#This Row],[HBA1C]]< 6.4,"prediabetes","diabetes")) -> diabetes | P24: Grand Total | Q24: 2335
A25: Id24 | B25: 41.8 | C25: 7.89 | D25: yes | E25: No | F25: No | G25: 2 | H25: yes | I25: =IF(Table4[[#This Row],[smoker]]="?","NO",Table4[[#This Row],[smoker]]) -> yes | J25: 2 | K25: =UPPER(Table4[[#This Row],[SMOKER 1]]) -> YES | L25: =UPPER(Table4[[#This Row],[Heart Issues]]) -> YES | M25: =IF(Table4[[#This Row],[BMI]]<18.5,"underweight",IF(Table4[[#This Row],[BMI]]< 24.9,"normal weight",IF(Table4[[#This Row],[BMI]]<29.9,"over weight","obesity"))) -> obesity | N25: =IF(Table4[[#This Row],[HBA1C]]<5.7,"normal",IF(Table4[[#This Row],[HBA1C]]< 6.4,"prediabetes","diabetes")) -> diabetes
A26: Id25 | B26: 35.09 | C26: 4.38 | D26: yes | E26: No | F26: No | G26: 2 | H26: yes | I26: =IF(Table4[[#This Row],[smoker]]="?","NO",Table4[[#This Row],[smoker]]) -> yes | J26: 2 | K26: =UPPER(Table4[[#This Row],[SMOKER 1]]) -> YES | L26: =UPPER(Table4[[#This Row],[Heart Issues]]) -> YES | M26: =IF(Table4[[#This Row],[BMI]]<18.5,"underweight",IF(Table4[[#This Row],[BMI]]< 24.9,"normal weight",IF(Table4[[#This Row],[BMI]]<29.9,"over weight","obesity"))) -> obesity | N26: =IF(Table4[[#This Row],[HBA1C]]<5.7,"normal",IF(Table4[[#This Row],[HBA1C]]< 6.4,"prediabetes","diabetes")) -> normal
A27: Id26 | B27: 33.88 | C27: 7.01 | D27: No | E27: No | F27: No | G27: 3 | H27: yes | I27: =IF(Table4[[#This Row],[smoker]]="?","NO",Table4[[#This Row],[smoker]]) -> yes | J27: 3 | K27: =UPPER(Table4[[#This Row],[SMOKER 1]]) -> YES | L27: =UPPER(Table4[[#This Row],[Heart Issues]]) -> NO | M27: =IF(Table4[[#This Row],[BMI]]<18.5,"underweight",IF(Table4[[#This Row],[BMI]]< 24.9,"normal weight",IF(Table4[[#This Row],[BMI]]<29.9,"over weight","obesity"))) -> obesity | N27: =IF(Table4[[#This Row],[HBA1C]]<5.7,"normal",IF(Table4[[#This Row],[HBA1C]]< 6.4,"prediabetes","diabetes")) -> diabetes
A28: Id27 | B28: 30.875 | C28: 11.88 | D28: No | E28: No | F28: No | G28: No major surgery | H28: yes | I28: =IF(Table4[[#This Row],[smoker]]="?","NO",Table4[[#This Row],[smoker]]) -> yes | J28: 0 | K28: =UPPER(Table4[[#This Row],[SMOKER 1]]) -> YES | L28: =UPPER(Table4[[#This Row],[Heart Issues]]) -> NO | M28: =IF(Table4[[#This Row],[BMI]]<18.5,"underweight",IF(Table4[[#This Row],[BMI]]< 24.9,"normal weight",IF(Table4[[#This Row],[BMI]]<29.9,"over weight","obesity"))) -> obesity | N28: =IF(Table4[[#This Row],[HBA1C]]<5.7,"normal",IF(Table4[[#This Row],[HBA1C]]< 6.4,"prediabetes","diabetes")) -> diabetes
A29: Id28 | B29: 36.86 | C29: 5.19 | D29: yes | E29: No | F29: Yes | G29: 1 | H29: yes | I29: =IF(Table4[[#This Row],[smoker]]="?","NO",Table4[[#This Row],[smoker]]) -> yes | J29: 1 | K29: =UPPER(Table4[[#This Row],[SMOKER 1]]) -> YES | L29: =UPPER(Table4[[#This Row],[Heart Issues]]) -> YES | M29: =IF(Table4[[#This Row],[BMI]]<18.5,"underweight",IF(Table4[[#This Row],[BMI]]< 24.9,"normal weight",IF(Table4[[#This Row],[BMI]]<29.9,"over weight","obesity"))) -> obesity | N29: =IF(Table4[[#This Row],[HBA1C]]<5.7,"normal",IF(Table4[[#This Row],[HBA1C]]< 6.4,"prediabetes","diabetes")) -> normal
A30: Id29 | B30: 35.86 | C30: 6.74 | D30: yes | E30: No | F30: No | G30: 2 | H30: yes | I30: =IF(Table4[[#This Row],[smoker]]="?","NO",Table4[[#This Row],[smoker]]) -> yes | J30: 2 | K30: =UPPER(Table4[[#This Row],[SMOKER 1]]) -> YES | L30: =UPPER(Table4[[#This Row],[Heart Issues]]) -> YES | M30: =IF(Table4[[#This Row],[BMI]]<18.5,"underweight",IF(Table4[[#This Row],[BMI]]< 24.9,"normal weight",IF(Table4[[#This Row],[BMI]]<29.9,"over weight","obesity"))) -> obesity | N30: =IF(Table4[[#This Row],[HBA1C]]<5.7,"normal",IF(Table4[[#This Row],[HBA1C]]< 6.4,"prediabetes","diabetes")) -> diabetes
A31: Id30 | B31: 37.05 | C31: 8.44 | D31: No | E31: No | F31: No | G31: No major surgery | H31: yes | I31: =IF(Table4[[#This Row],[smoker]]="?","NO",Table4[[#This Row],[smoker]]) -> yes | J31: 0 | K31: =UPPER(Table4[[#This Row],[SMOKER 1]]) -> YES | L31: =UPPER(Table4[[#This Row],[Heart Issues]]) -> NO | M31: =IF(Table4[[#This Row],[BMI]]<18.5,"underweight",IF(Table4[[#This Row],[BMI]]< 24.9,"normal weight",IF(Table4[[#This Row],[BMI]]<29.9,"over weight","obesity"))) -> obesity | N31: =IF(Table4[[#This Row],[HBA1C]]<5.7,"normal",IF(Table4[[#This Row],[HBA1C]]< 6.4,"prediabetes","diabetes")) -> diabetes
A32: Id31 | B32: 43.89 | C32: 8.71 | D32: No | E32: No | F32: No | G32: No major surgery | H32: yes | I32: =IF(Table4[[#This Row],[smoker]]="?","NO",Table4[[#This Row],[smoker]]) -> yes | J32: 0 | K32: =UPPER(Table4[[#This Row],[SMOKER 1]]) -> YES | L32: =UPPER(Table4[[#This Row],[Heart Issues]]) -> NO | M32: =IF(Table4[[#This Row],[BMI]]<18.5,"underweight",IF(Table4[[#This Row],[BMI]]< 24.9,"normal weight",IF(Table4[[#This Row],[BMI]]<29.9,"over weight","obesity"))) -> obesity | N32: =IF(Table4[[#This Row],[HBA1C]]<5.7,"normal",IF(Table4[[#This Row],[HBA1C]]< 6.4,"prediabetes","diabetes")) -> diabetes
A33: Id32 | B33: 42.35 | C33: 5.08 | D33: yes | E33: No | F33: No | G33: No major surgery | H33: yes | I33: =IF(Table4[[#This Row],[smoker]]="?","NO",Table4[[#This Row],[smoker]]) -> yes | J33: 0 | K33: =UPPER(Table4[[#This Row],[SMOKER 1]]) -> YES | L33: =UPPER(Table4[[#This Row],[Heart Issues]]) -> YES | M33: =IF(Table4[[#This Row],[BMI]]<18.5,"underweight",IF(Table4[[#This Row],[BMI]]< 24.9,"normal weight",IF(Table4[[#This Row],[BMI]]<29.9,"over weight","obesity"))) -> obesity | N33: =IF(Table4[[#This Row],[HBA1C]]<5.7,"normal",IF(Table4[[#This Row],[HBA1C]]< 6.4,"prediabetes","diabetes")) -> normal
A34: Id33 | B34: 31.35 | C34: 6.86 | D34: No | E34: No | F34: No | G34: No major surgery | H34: yes | I34: =IF(Table4[[#This Row],[smoker]]="?","NO",Table4[[#This Row],[smoker]]) -> yes | J34: 0 | K34: =UPPER(Table4[[#This Row],[SMOKER 1]]) -> YES | L34: =UPPER(Table4[[#This Row],[Heart Issues]]) -> NO | M34: =IF(Table4[[#This Row],[BMI]]<18.5,"underweight",IF(Table4[[#This Row],[BMI]]< 24.9,"normal weight",IF(Table4[[#This Row],[BMI]]<29.9,"over weight","obesity"))) -> obesity | N34: =IF(Table4[[#This Row],[HBA1C]]<5.7,"normal",IF(Table4[[#This Row],[HBA1C]]< 6.4,"prediabetes","diabetes")) -> diabetes
A35: Id34 | B35: 47.6 | C35: 5.95 | D35: yes | E35: No | F35: No | G35: No major surgery | H35: yes | I35: =IF(Table4[[#This Row],[smoker]]="?","NO",Table4[[#This Row],[smoker]]) -> yes | J35: 0 | K35: =UPPER(Table4[[#This Row],[SMOKER 1]]) -> YES | L35: =UPPER(Table4[[#This Row],[Heart Issues]]) -> YES | M35: =IF(Table4[[#This Row],[BMI]]<18.5,"underweight",IF(Table4[[#This Row],[BMI]]< 24.9,"normal weight",IF(Table4[[#This Row],[BMI]]<29.9,"over weight","obesity"))) -> obesity | N35: =IF(Table4[[#This Row],[HBA1C]]<5.7,"normal",IF(Table4[[#This Row],[HBA1C]]< 6.4,"prediabetes","diabetes")) -> prediabetes
A36: Id35 | B36: 46.2 | C36: 6.09 | D36: No | E36: No | F36: Yes | G36: 1 | H36: yes | I36: =IF(Table4[[#This Row],[smoker]]="?","NO",Table4[[#This Row],[smoker]]) -> yes | J36: 1 | K36: =UPPER(Table4[[#This Row],[SMOKER 1]]) -> YES | L36: =UPPER(Table4[[#This Row],[Heart Issues]]) -> NO | M36: =IF(Table4[[#This Row],[BMI]]<18.5,"underweight",IF(Table4[[#This Row],[BMI]]< 24.9,"normal weight",IF(Table4[[#This Row],[BMI]]<29.9,"over weight","obesity"))) -> obesity | N36: =IF(Table4[[#This Row],[HBA1C]]<5.7,"normal",IF(Table4[[#This Row],[HBA1C]]< 6.4,"prediabetes","diabetes")) -> prediabetes
A37: Id36 | B37: 32.015 | C37: 11.75 | D37: No | E37: No | F37: No | G37: No major surgery | H37: yes | I37: =IF(Table4[[#This Row],[smoker]]="?","NO",Table4[[#This Row],[smoker]]) -> yes | J37: 0 | K37: =UPPER(Table4[[#This Row],[SMOKER 1]]) -> YES | L37: =UPPER(Table4[[#This Row],[Heart Issues]]) -> NO | M37: =IF(Table4[[#This Row],[BMI]]<18.5,"underweight",IF(Table4[[#This Row],[BMI]]< 24.9,"normal weight",IF(Table4[[#This Row],[BMI]]<29.9,"over weight","obesity"))) -> obesity | N37: =IF(Table4[[#This Row],[HBA1C]]<5.7,"normal",IF(Table4[[#This Row],[HBA1C]]< 6.4,"prediabetes","diabetes")) -> diabetes
A38: Id37 | B38: 40.565 | C38: 7.37 | D38: No | E38: No | F38: No | G38: No major surgery | H38: yes | I38: =IF(Table4[[#This Row],[smoker]]="?","NO",Table4[[#This Row],[smoker]]) -> yes | J38: 0 | K38: =UPPER(Table4[[#This Row],[SMOKER 1]]) -> YES | L38: =UPPER(Table4[[#This Row],[Heart Issues]]) -> NO | M38: =IF(Table4[[#This Row],[BMI]]<18.5,"underweight",IF(Table4[[#This Row],[BMI]]< 24.9,"normal weight",IF(Table4[[#This Row],[BMI]]<29.9,"over weight","obesity"))) -> obesity | N38: =IF(Table4[[#This Row],[HBA1C]]<5.7,"normal",IF(Table4[[#This Row],[HBA1C]]< 6.4,"prediabetes","diabetes")) -> diabetes
A39: Id38 | B39: 32.45 | C39: 11.91 | D39: No | E39: No | F39: No | G39: No major surgery | H39: yes | I39: =IF(Table4[[#This Row],[smoker]]="?","NO",Table4[[#This Row],[smoker]]) -> yes | J39: 0 | K39: =UPPER(Table4[[#This Row],[SMOKER 1]]) -> YES | L39: =UPPER(Table4[[#This Row],[Heart Issues]]) -> NO | M39: =IF(Table4[[#This Row],[BMI]]<18.5,"underweight",IF(Table4[[#This Row],[BMI]]< 24.9,"normal weight",IF(Table4[[#This Row],[BMI]]<29.9,"over weight","obesity"))) -> obesity | N39: =IF(Table4[[#This Row],[HBA1C]]<5.7,"normal",IF(Table4[[#This Row],[HBA1C]]< 6.4,"prediabetes","diabetes")) -> diabetes
A40: Id39 | B40: 34.96 | C40: 6.52 | D40: No | E40: No | F40: No | G40: No major surgery | H40: yes | I40: =IF(Table4[[#This Row],[smoker]]="?","NO",Table4[[#This Row],[smoker]]) -> yes | J40: 0 | K40: =UPPER(Table4[[#This Row],[SMOKER 1]]) -> YES | L40: =UPPER(Table4[[#This Row],[Heart Issues]]) -> NO | M40: =IF(Table4[[#This Row],[BMI]]<18.5,"underweight",IF(Table4[[#This Row],[BMI]]< 24.9,"normal weight",IF(Table4[[#This Row],[BMI]]<29.9,"over weight","obesity"))) -> obesity | N40: =IF(Table4[[#This Row],[HBA1C]]<5.7,"normal",IF(Table4[[#This Row],[HBA1C]]< 6.4,"prediabetes","diabetes")) -> diabetes
...

Sheet Hospitalisation Details
A1: Customer ID | B1: year | C1: month | D1: date | E1: children | F1: charges | G1: Hospital tier | H1: City tier | I1: State ID | J1: month2 | K1: year2 | L1: HOSPITAL TIER2 | M1: city tier2 | N1: state id2 | O1: date of birth | P1: age | Q1: charges2
A2: Id2335 | B2: 1992 | C2: Jul | D2: 9 | E2: 0 | F2: 563.84 | G2: tier - 2 | H2: tier - 3 | I2: R1013 | J2: =IF(Table3[[#This Row],[month]]="?","sep",Table3[[#This Row],[month]]) -> Jul | K2: =IF(Table3[[#This Row],[year]]="?","1983",Table3[[#This Row],[year]]) -> 1992 | L2: =IF(Table3[[#This Row],[Hospital tier]]="?","tier - 2",Table3[[#This Row],[Hospital tier]]) -> tier - 2 | M2: =IF(Table3[[#This Row],[City tier]]="?","tier - 2",Table3[[#This Row],[City tier]]) -> tier - 3 | N2: =IF(Table3[[#This Row],[State ID]]="?","unknown",Table3[[#This Row],[State ID]]) -> R1013 | O2: =CONCATENATE(Table3[[#This Row],[date]],"-",Table3[[#This Row],[month2]],"-",Table3[[#This Row],[year2]]) -> 9-Jul-1992 | P2: =DATEDIF(Table3[[#This Row],[date of birth]],DATE(2023,6,8),"y") -> 30 | Q2: 563.84
A3: Id2336 | B3: 1992 | C3: Nov | D3: 30 | E3: 0 | F3: 570.62 | G3: tier - 2 | H3: tier - 1 | I3: R1013 | J3: =IF(Table3[[#This Row],[month]]="?","sep",Table3[[#This Row],[month]]) -> Nov | K3: =IF(Table3[[#This Row],[year]]="?","1983",Table3[[#This Row],[year]]) -> 1992 | L3: =IF(Table3[[#This Row],[Hospital tier]]="?","tier - 2",Table3[[#This Row],[Hospital tier]]) -> tier - 2 | M3: =IF(Table3[[#This Row],[City tier]]="?","tier - 2",Table3[[#This Row],[City tier]]) -> tier - 1 | N3: =IF(Table3[[#This Row],[State ID]]="?","unknown",Table3[[#This Row],[State ID]]) -> R1013 | O3: =CONCATENATE(Table3[[#This Row],[date]],"-",Table3[[#This Row],[month2]],"-",Table3[[#This Row],[year2]]) -> 30-Nov-1992 | P3: =DATEDIF(Table3[[#This Row],[date of birth]],DATE(2023,6,8),"y") -> 30 | Q3: 570.62
A4: Id2337 | B4: 1993 | C4: Jun | D4: 30 | E4: 0 | F4: 600 | G4: tier - 2 | H4: tier - 1 | I4: R1013 | J4: =IF(Table3[[#This Row],[month]]="?","sep",Table3[[#This Row],[month]]) -> Jun | K4: =IF(Table3[[#This Row],[year]]="?","1983",Table3[[#This Row],[year]]) -> 1993 | L4: =IF(Table3[[#This Row],[Hospital tier]]="?","tier - 2",Table3[[#This Row],[Hospital tier]]) -> tier - 2 | M4: =IF(Table3[[#This Row],[City tier]]="?","tier - 2",Table3[[#This Row],[City tier]]) -> tier - 1 | N4: =IF(Table3[[#This Row],[State ID]]="?","unknown",Table3[[#This Row],[State ID]]) -> R1013 | O4: =CONCATENATE(Table3[[#This Row],[date]],"-",Table3[[#This Row],[month2]],"-",Table3[[#This Row],[year2]]) -> 30-Jun-1993 | P4: =DATEDIF(Table3[[#This Row],[date of birth]],DATE(2023,6,8),"y") -> 29 | Q4: 600 | S4: average of year | T4: =AVERAGE(Table3[year]) -> 1982.8415
A5: Id2338 | B5: 1992 | C5: Sep | D5: 13 | E5: 0 | F5: 604.54 | G5: tier - 3 | H5: tier - 3 | I5: R1013 | J5: =IF(Table3[[#This Row],[month]]="?","sep",Table3[[#This Row],[month]]) -> Sep | K5: =IF(Table3[[#This Row],[year]]="?","1983",Table3[[#This Row],[year]]) -> 1992 | L5: =IF(Table3[[#This Row],[Hospital tier]]="?","tier - 2",Table3[[#This Row],[Hospital tier]]) -> tier - 3 | M5: =IF(Table3[[#This Row],[City tier]]="?","tier - 2",Table3[[#This Row],[City tier]]) -> tier - 3 | N5: =IF(Table3[[#This Row],[State ID]]="?","unknown",Table3[[#This Row],[State ID]]) -> R1013 | O5: =CONCATENATE(Table3[[#This Row],[date]],"-",Table3[[#This Row],[month2]],"-",Table3[[#This Row],[year2]]) -> 13-Sep-1992 | P5: =DATEDIF(Table3[[#This Row],[date of birth]],DATE(2023,6,8),"y") -> 30 | Q5: 604.54
A6: Id2339 | B6: 1998 | C6: Jul | D6: 27 | E6: 0 | F6: 637.26 | G6: tier - 3 | H6: tier - 3 | I6: R1013 | J6: =IF(Table3[[#This Row],[month]]="?","sep",Table3[[#This Row],[month]]) -> Jul | K6: =IF(Table3[[#This Row],[year]]="?","1983",Table3[[#This Row],[year]]) -> 1998 | L6: =IF(Table3[[#This Row],[Hospital tier]]="?","tier - 2",Table3[[#This Row],[Hospital tier]]) -> tier - 3 | M6: =IF(Table3[[#This Row],[City tier]]="?","tier - 2",Table3[[#This Row],[City tier]]) -> tier - 3 | N6: =IF(Table3[[#This Row],[State ID]]="?","unknown",Table3[[#This Row],[State ID]]) -> R1013 | O6: =CONCATENATE(Table3[[#This Row],[date]],"-",Table3[[#This Row],[month2]],"-",Table3[[#This Row],[year2]]) -> 27-Jul-1998 | P6: =DATEDIF(Table3[[#This Row],[date of birth]],DATE(2023,6,8),"y") -> 24 | Q6: 637.26
A7: Id2340 | B7: 2001 | C7: Nov | D7: 20 | E7: 0 | F7: 646.14 | G7: tier - 3 | H7: tier - 3 | I7: R1012 | J7: =IF(Table3[[#This Row],[month]]="?","sep",Table3[[#This Row],[month]]) -> Nov | K7: =IF(Table3[[#This Row],[year]]="?","1983",Table3[[#This Row],[year]]) -> 2001 | L7: =IF(Table3[[#This Row],[Hospital tier]]="?","tier - 2",Table3[[#This Row],[Hospital tier]]) -> tier - 3 | M7: =IF(Table3[[#This Row],[City tier]]="?","tier - 2",Table3[[#This Row],[City tier]]) -> tier - 3 | N7: =IF(Table3[[#This Row],[State ID]]="?","unknown",Table3[[#This Row],[State ID]]) -> R1012 | O7: =CONCATENATE(Table3[[#This Row],[date]],"-",Table3[[#This Row],[month2]],"-",Table3[[#This Row],[year2]]) -> 20-Nov-2001 | P7: =DATEDIF(Table3[[#This Row],[date of birth]],DATE(2023,6,8),"y") -> 21 | Q7: 646.14 | S7: CUSTOMER ID | T7: =COUNTIF(A2:A2336,"?") -> 0
A8: Id2341 | B8: 1993 | C8: Jun | D8: 1 | E8: 0 | F8: 650 | G8: tier - 3 | H8: tier - 3 | I8: R1013 | J8: =IF(Table3[[#This Row],[month]]="?","sep",Table3[[#This Row],[month]]) -> Jun | K8: =IF(Table3[[#This Row],[year]]="?","1983",Table3[[#This Row],[year]]) -> 1993 | L8: =IF(Table3[[#This Row],[Hospital tier]]="?","tier - 2",Table3[[#This Row],[Hospital tier]]) -> tier - 3 | M8: =IF(Table3[[#This Row],[City tier]]="?","tier - 2",Table3[[#This Row],[City tier]]) -> tier - 3 | N8: =IF(Table3[[#This Row],[State ID]]="?","unknown",Table3[[#This Row],[State ID]]) -> R1013 | O8: =CONCATENATE(Table3[[#This Row],[date]],"-",Table3[[#This Row],[month2]],"-",Table3[[#This Row],[year2]]) -> 1-Jun-1993 | P8: =DATEDIF(Table3[[#This Row],[date of birth]],DATE(2023,6,8),"y") -> 30 | Q8: 650 | S8: YEAR | T8: =COUNTIF(B2:B2344,"?") -> 2
A9: Id2342 | B9: 1995 | C9: Jul | D9: 4 | E9: 0 | F9: 650 | G9: tier - 3 | H9: tier - 3 | I9: R1013 | J9: =IF(Table3[[#This Row],[month]]="?","sep",Table3[[#This Row],[month]]) -> Jul | K9: =IF(Table3[[#This Row],[year]]="?","1983",Table3[[#This Row],[year]]) -> 1995 | L9: =IF(Table3[[#This Row],[Hospital tier]]="?","tier - 2",Table3[[#This Row],[Hospital tier]]) -> tier - 3 | M9: =IF(Table3[[#This Row],[City tier]]="?","tier - 2",Table3[[#This Row],[City tier]]) -> tier - 3 | N9: =IF(Table3[[#This Row],[State ID]]="?","unknown",Table3[[#This Row],[State ID]]) -> R1013 | O9: =CONCATENATE(Table3[[#This Row],[date]],"-",Table3[[#This Row],[month2]],"-",Table3[[#This Row],[year2]]) -> 4-Jul-1995 | P9: =DATEDIF(Table3[[#This Row],[date of birth]],DATE(2023,6,8),"y") -> 27 | Q9: 650 | S9: month | T9: =COUNTIF(C2:C2344,"?") -> 3
A10: Id2343 | B10: 2002 | C10: Nov | D10: 29 | E10: 0 | F10: 668 | G10: tier - 3 | H10: tier - 2 | I10: R1012 | J10: =IF(Table3[[#This Row],[month]]="?","sep",Table3[[#This Row],[month]]) -> Nov | K10: =IF(Table3[[#This Row],[year]]="?","1983",Table3[[#This Row],[year]]) -> 2002 | L10: =IF(Table3[[#This Row],[Hospital tier]]="?","tier - 2",Table3[[#This Row],[Hospital tier]]) -> tier - 3 | M10: =IF(Table3[[#This Row],[City tier]]="?","tier - 2",Table3[[#This Row],[City tier]]) -> tier - 2 | N10: =IF(Table3[[#This Row],[State ID]]="?","unknown",Table3[[#This Row],[State ID]]) -> R1012 | O10: =CONCATENATE(Table3[[#This Row],[date]],"-",Table3[[#This Row],[month2]],"-",Table3[[#This Row],[year2]]) -> 29-Nov-2002 | P10: =DATEDIF(Table3[[#This Row],[date of birth]],DATE(2023,6,8),"y") -> 20 | Q10: 668 | S10: date | T10: =COUNTIF(D2:D2344,"?") -> 0
A11: Id2344 | B11: 1997 | C11: Nov | D11: 9 | E11: 0 | F11: 670 | G11: tier - 3 | H11: tier - 3 | I11: R1013 | J11: =IF(Table3[[#This Row],[month]]="?","sep",Table3[[#This Row],[month]]) -> Nov | K11: =IF(Table3[[#This Row],[year]]="?","1983",Table3[[#This Row],[year]]) -> 1997 | L11: =IF(Table3[[#This Row],[Hospital tier]]="?","tier - 2",Table3[[#This Row],[Hospital tier]]) -> tier - 3 | M11: =IF(Table3[[#This Row],[City tier]]="?","tier - 2",Table3[[#This Row],[City tier]]) -> tier - 3 | N11: =IF(Table3[[#This Row],[State ID]]="?","unknown",Table3[[#This Row],[State ID]]) -> R1013 | O11: =CONCATENATE(Table3[[#This Row],[date]],"-",Table3[[#This Row],[month2]],"-",Table3[[#This Row],[year2]]) -> 9-Nov-1997 | P11: =DATEDIF(Table3[[#This Row],[date of birth]],DATE(2023,6,8),"y") -> 25 | Q11: 670 | S11: children | T11: =COUNTIF(E2:E2344,"?") -> 0
A12: Id2345 | B12: 2001 | C12: Sep | D12: 12 | E12: 0 | F12: 687.54 | G12: tier - 3 | H12: tier - 2 | I12: R1013 | J12: =IF(Table3[[#This Row],[month]]="?","sep",Table3[[#This Row],[month]]) -> Sep | K12: =IF(Table3[[#This Row],[year]]="?","1983",Table3[[#This Row],[year]]) -> 2001 | L12: =IF(Table3[[#This Row],[Hospital tier]]="?","tier - 2",Table3[[#This Row],[Hospital tier]]) -> tier - 3 | M12: =IF(Table3[[#This Row],[City tier]]="?","tier - 2",Table3[[#This Row],[City tier]]) -> tier - 2 | N12: =IF(Table3[[#This Row],[State ID]]="?","unknown",Table3[[#This Row],[State ID]]) -> R1013 | O12: =CONCATENATE(Table3[[#This Row],[date]],"-",Table3[[#This Row],[month2]],"-",Table3[[#This Row],[year2]]) -> 12-Sep-2001 | P12: =DATEDIF(Table3[[#This Row],[date of birth]],DATE(2023,6,8),"y") -> 21 | Q12: 687.54 | S12: charges | T12: =COUNTIF(F2:F2344,"?") -> 0
A13: Id2346 | B13: 1999 | C13: Dec | D13: 26 | E13: 0 | F13: 700 | G13: ? | H13: tier - 3 | I13: R1013 | J13: =IF(Table3[[#This Row],[month]]="?","sep",Table3[[#This Row],[month]]) -> Dec | K13: =IF(Table3[[#This Row],[year]]="?","1983",Table3[[#This Row],[year]]) -> 1999 | L13: =IF(Table3[[#This Row],[Hospital tier]]="?","tier - 2",Table3[[#This Row],[Hospital tier]]) -> tier - 2 | M13: =IF(Table3[[#This Row],[City tier]]="?","tier - 2",Table3[[#This Row],[City tier]]) -> tier - 3 | N13: =IF(Table3[[#This Row],[State ID]]="?","unknown",Table3[[#This Row],[State ID]]) -> R1013 | O13: =CONCATENATE(Table3[[#This Row],[date]],"-",Table3[[#This Row],[month2]],"-",Table3[[#This Row],[year2]]) -> 26-Dec-1999 | P13: =DATEDIF(Table3[[#This Row],[date of birth]],DATE(2023,6,8),"y") -> 23 | Q13: 700 | S13: Hospital tier | T13: =COUNTIF(G2:G2344,"?") -> 1
A14: Id2347 | B14: 1999 | C14: Dec | D14: 14 | E14: 0 | F14: 722.99 | G14: tier - 3 | H14: tier - 1 | I14: R1013 | J14: =IF(Table3[[#This Row],[month]]="?","sep",Table3[[#This Row],[month]]) -> Dec | K14: =IF(Table3[[#This Row],[year]]="?","1983",Table3[[#This Row],[year]]) -> 1999 | L14: =IF(Table3[[#This Row],[Hospital tier]]="?","tier - 2",Table3[[#This Row],[Hospital tier]]) -> tier - 3 | M14: =IF(Table3[[#This Row],[City tier]]="?","tier - 2",Table3[[#This Row],[City tier]]) -> tier - 1 | N14: =IF(Table3[[#This Row],[State ID]]="?","unknown",Table3[[#This Row],[State ID]]) -> R1013 | O14: =CONCATENATE(Table3[[#This Row],[date]],"-",Table3[[#This Row],[month2]],"-",Table3[[#This Row],[year2]]) -> 14-Dec-1999 | P14: =DATEDIF(Table3[[#This Row],[date of birth]],DATE(2023,6,8),"y") -> 23 | Q14: 722.99 | S14: City tier | T14: =COUNTIF(H2:H2344,"?") -> 1
A15: Id2348 | B15: 2002 | C15: ? | D15: 19 | E15: 0 | F15: 750 | G15: tier - 3 | H15: tier - 1 | I15: R1012 | J15: =IF(Table3[[#This Row],[month]]="?","sep",Table3[[#This Row],[month]]) -> sep | K15: =IF(Table3[[#This Row],[year]]="?","1983",Table3[[#This Row],[year]]) -> 2002 | L15: =IF(Table3[[#This Row],[Hospital tier]]="?","tier - 2",Table3[[#This Row],[Hospital tier]]) -> tier - 3 | M15: =IF(Table3[[#This Row],[City tier]]="?","tier - 2",Table3[[#This Row],[City tier]]) -> tier - 1 | N15: =IF(Table3[[#This Row],[State ID]]="?","unknown",Table3[[#This Row],[State ID]]) -> R1012 | O15: =CONCATENATE(Table3[[#This Row],[date]],"-",Table3[[#This Row],[month2]],"-",Table3[[#This Row],[year2]]) -> 19-sep-2002 | P15: =DATEDIF(Table3[[#This Row],[date of birth]],DATE(2023,6,8),"y") -> 20 | Q15: 750 | S15: State ID | T15: =COUNTIF(I2:I2344,"?") -> 2
A16: Id2349 | B16: 1993 | C16: Aug | D16: 9 | E16: 0 | F16: 760 | G16: tier - 3 | H16: tier - 1 | I16: R1013 | J16: =IF(Table3[[#This Row],[month]]="?","sep",Table3[[#This Row],[month]]) -> Aug | K16: =IF(Table3[[#This Row],[year]]="?","1983",Table3[[#This Row],[year]]) -> 1993 | L16: =IF(Table3[[#This Row],[Hospital tier]]="?","tier - 2",Table3[[#This Row],[Hospital tier]]) -> tier - 3 | M16: =IF(Table3[[#This Row],[City tier]]="?","tier - 2",Table3[[#This Row],[City tier]]) -> tier - 1 | N16: =IF(Table3[[#This Row],[State ID]]="?","unknown",Table3[[#This Row],[State ID]]) -> R1013 | O16: =CONCATENATE(Table3[[#This Row],[date]],"-",Table3[[#This Row],[month2]],"-",Table3[[#This Row],[year2]]) -> 9-Aug-1993 | P16: =DATEDIF(Table3[[#This Row],[date of birth]],DATE(2023,6,8),"y") -> 29 | Q16: 760
A17: Id2350 | B17: 1996 | C17: Oct | D17: 22 | E17: 0 | F17: 760 | G17: tier - 3 | H17: tier - 3 | I17: R1013 | J17: =IF(Table3[[#This Row],[month]]="?","sep",Table3[[#This Row],[month]]) -> Oct | K17: =IF(Table3[[#This Row],[year]]="?","1983",Table3[[#This Row],[year]]) -> 1996 | L17: =IF(Table3[[#This Row],[Hospital tier]]="?","tier - 2",Table3[[#This Row],[Hospital tier]]) -> tier - 3 | M17: =IF(Table3[[#This Row],[City tier]]="?","tier - 2",Table3[[#This Row],[City tier]]) -> tier - 3 | N17: =IF(Table3[[#This Row],[State ID]]="?","unknown",Table3[[#This Row],[State ID]]) -> R1013 | O17: =CONCATENATE(Table3[[#This Row],[date]],"-",Table3[[#This Row],[month2]],"-",Table3[[#This Row],[year2]]) -> 22-Oct-1996 | P17: =DATEDIF(Table3[[#This Row],[date of birth]],DATE(2023,6,8),"y") -> 26 | Q17: 760
A18: Id2351 | B18: 1993 | C18: Jun | D18: 28 | E18: 0 | F18: 770 | G18: tier - 3 | H18: tier - 3 | I18: R1013 | J18: =IF(Table3[[#This Row],[month]]="?","sep",Table3[[#This Row],[month]]) -> Jun | K18: =IF(Table3[[#This Row],[year]]="?","1983",Table3[[#This Row],[year]]) -> 1993 | L18: =IF(Table3[[#This Row],[Hospital tier]]="?","tier - 2",Table3[[#This Row],[Hospital tier]]) -> tier - 3 | M18: =IF(Table3[[#This Row],[City tier]]="?","tier - 2",Table3[[#This Row],[City tier]]) -> tier - 3 | N18: =IF(Table3[[#This Row],[State ID]]="?","unknown",Table3[[#This Row],[State ID]]) -> R1013 | O18: =CONCATENATE(Table3[[#This Row],[date]],"-",Table3[[#This Row],[month2]],"-",Table3[[#This Row],[year2]]) -> 28-Jun-1993 | P18: =DATEDIF(Table3[[#This Row],[date of birth]],DATE(2023,6,8),"y") -> 29 | Q18: 770 | S18: Mode of hosptl tier
A19: Id2352 | B19: 1996 | C19: ? | D19: 18 | E19: 0 | F19: 770.38 | G19: tier - 3 | H19: ? | I19: R1012 | J19: =IF(Table3[[#This Row],[month]]="?","sep",Table3[[#This Row],[month]]) -> sep | K19: =IF(Table3[[#This Row],[year]]="?","1983",Table3[[#This Row],[year]]) -> 1996 | L19: =IF(Table3[[#This Row],[Hospital tier]]="?","tier - 2",Table3[[#This Row],[Hospital tier]]) -> tier - 3 | M19: =IF(Table3[[#This Row],[City tier]]="?","tier - 2",Table3[[#This Row],[City tier]]) -> tier - 2 | N19: =IF(Table3[[#This Row],[State ID]]="?","unknown",Table3[[#This Row],[State ID]]) -> R1012 | O19: =CONCATENATE(Table3[[#This Row],[date]],"-",Table3[[#This Row],[month2]],"-",Table3[[#This Row],[year2]]) -> 18-sep-1996 | P19: =DATEDIF(Table3[[#This Row],[date of birth]],DATE(2023,6,8),"y") -> 26 | Q19: 770.38 | S19: Row Labels | T19: Count of Hospital tier
A20: Id2353 | B20: 1995 | C20: Dec | D20: 7 | E20: 0 | F20: 773.54 | G20: tier - 3 | H20: tier - 2 | I20: R1013 | J20: =IF(Table3[[#This Row],[month]]="?","sep",Table3[[#This Row],[month]]) -> Dec | K20: =IF(Table3[[#This Row],[year]]="?","1983",Table3[[#This Row],[year]]) -> 1995 | L20: =IF(Table3[[#This Row],[Hospital tier]]="?","tier - 2",Table3[[#This Row],[Hospital tier]]) -> tier - 3 | M20: =IF(Table3[[#This Row],[City tier]]="?","tier - 2",Table3[[#This Row],[City tier]]) -> tier - 2 | N20: =IF(Table3[[#This Row],[State ID]]="?","unknown",Table3[[#This Row],[State ID]]) -> R1013 | O20: =CONCATENATE(Table3[[#This Row],[date]],"-",Table3[[#This Row],[month2]],"-",Table3[[#This Row],[year2]]) -> 7-Dec-1995 | P20: =DATEDIF(Table3[[#This Row],[date of birth]],DATE(2023,6,8),"y") -> 27 | Q20: 773.54 | S20: ? | T20: 1
A21: Id2354 | B21: 2004 | C21: Oct | D21: 7 | E21: 0 | F21: 830.52 | G21: tier - 3 | H21: tier - 2 | I21: R1011 | J21: =IF(Table3[[#This Row],[month]]="?","sep",Table3[[#This Row],[month]]) -> Oct | K21: =IF(Table3[[#This Row],[year]]="?","1983",Table3[[#This Row],[year]]) -> 2004 | L21: =IF(Table3[[#This Row],[Hospital tier]]="?","tier - 2",Table3[[#This Row],[Hospital tier]]) -> tier - 3 | M21: =IF(Table3[[#This Row],[City tier]]="?","tier - 2",Table3[[#This Row],[City tier]]) -> tier - 2 | N21: =IF(Table3[[#This Row],[State ID]]="?","unknown",Table3[[#This Row],[State ID]]) -> R1011 | O21: =CONCATENATE(Table3[[#This Row],[date]],"-",Table3[[#This Row],[month2]],"-",Table3[[#This Row],[year2]]) -> 7-Oct-2004 | P21: =DATEDIF(Table3[[#This Row],[date of birth]],DATE(2023,6,8),"y") -> 18 | Q21: 830.52 | S21: tier - 1 | T21: 309
A22: Id2355 | B22: 2000 | C22: Nov | D22: 18 | E22: 0 | F22: 865.41 | G22: tier - 3 | H22: tier - 1 | I22: R1013 | J22: =IF(Table3[[#This Row],[month]]="?","sep",Table3[[#This Row],[month]]) -> Nov | K22: =IF(Table3[[#This Row],[year]]="?","1983",Table3[[#This Row],[year]]) -> 2000 | L22: =IF(Table3[[#This Row],[Hospital tier]]="?","tier - 2",Table3[[#This Row],[Hospital tier]]) -> tier - 3 | M22: =IF(Table3[[#This Row],[City tier]]="?","tier - 2",Table3[[#This Row],[City tier]]) -> tier - 1 | N22: =IF(Table3[[#This Row],[State ID]]="?","unknown",Table3[[#This Row],[State ID]]) -> R1013 | O22: =CONCATENATE(Table3[[#This Row],[date]],"-",Table3[[#This Row],[month2]],"-",Table3[[#This Row],[year2]]) -> 18-Nov-2000 | P22: =DATEDIF(Table3[[#This Row],[date of birth]],DATE(2023,6,8),"y") -> 22 | Q22: 865.41 | S22: tier - 2 | T22: 1339
A23: Id2356 | B23: 1993 | C23: Nov | D23: 27 | E23: 0 | F23: 896.21 | G23: tier - 3 | H23: tier - 1 | I23: R1013 | J23: =IF(Table3[[#This Row],[month]]="?","sep",Table3[[#This Row],[month]]) -> Nov | K23: =IF(Table3[[#This Row],[year]]="?","1983",Table3[[#This Row],[year]]) -> 1993 | L23: =IF(Table3[[#This Row],[Hospital tier]]="?","tier - 2",Table3[[#This Row],[Hospital tier]]) -> tier - 3 | M23: =IF(Table3[[#This Row],[City tier]]="?","tier - 2",Table3[[#This Row],[City tier]]) -> tier - 1 | N23: =IF(Table3[[#This Row],[State ID]]="?","unknown",Table3[[#This Row],[State ID]]) -> R1013 | O23: =CONCATENATE(Table3[[#This Row],[date]],"-",Table3[[#This Row],[month2]],"-",Table3[[#This Row],[year2]]) -> 27-Nov-1993 | P23: =DATEDIF(Table3[[#This Row],[date of birth]],DATE(2023,6,8),"y") -> 29 | Q23: 896.21 | S23: tier - 3 | T23: 694
A24: Id2357 | B24: 1994 | C24: Oct | D24: 30 | E24: 0 | F24: 915.07 | G24: tier - 3 | H24: tier - 1 | I24: R1013 | J24: =IF(Table3[[#This Row],[month]]="?","sep",Table3[[#This Row],[month]]) -> Oct | K24: =IF(Table3[[#This Row],[year]]="?","1983",Table3[[#This Row],[year]]) -> 1994 | L24: =IF(Table3[[#This Row],[Hospital tier]]="?","tier - 2",Table3[[#This Row],[Hospital tier]]) -> tier - 3 | M24: =IF(Table3[[#This Row],[City tier]]="?","tier - 2",Table3[[#This Row],[City tier]]) -> tier - 1 | N24: =IF(Table3[[#This Row],[State ID]]="?","unknown",Table3[[#This Row],[State ID]]) -> R1013 | O24: =CONCATENATE(Table3[[#This Row],[date]],"-",Table3[[#This Row],[month2]],"-",Table3[[#This Row],[year2]]) -> 30-Oct-1994 | P24: =DATEDIF(Table3[[#This Row],[date of birth]],DATE(2023,6,8),"y") -> 28 | Q24: 915.07 | S24: Grand Total | T24: 2343
A25: Id2358 | B25: 1995 | C25: Oct | D25: 28 | E25: 0 | F25: 928.59 | G25: tier - 3 | H25: tier - 1 | I25: R1013 | J25: =IF(Table3[[#This Row],[month]]="?","sep",Table3[[#This Row],[month]]) -> Oct | K25: =IF(Table3[[#This Row],[year]]="?","1983",Table3[[#This Row],[year]]) -> 1995 | L25: =IF(Table3[[#This Row],[Hospital tier]]="?","tier - 2",Table3[[#This Row],[Hospital tier]]) -> tier - 3 | M25: =IF(Table3[[#This Row],[City tier]]="?","tier - 2",Table3[[#This Row],[City tier]]) -> tier - 1 | N25: =IF(Table3[[#This Row],[State ID]]="?","unknown",Table3[[#This Row],[State ID]]) -> R1013 | O25: =CONCATENATE(Table3[[#This Row],[date]],"-",Table3[[#This Row],[month2]],"-",Table3[[#This Row],[year2]]) -> 28-Oct-1995 | P25: =DATEDIF(Table3[[#This Row],[date of birth]],DATE(2023,6,8),"y") -> 27 | Q25: 928.59
A26: Id2359 | B26: 2001 | C26: Aug | D26: 19 | E26: 0 | F26: 964.71 | G26: tier - 3 | H26: tier - 2 | I26: R1013 | J26: =IF(Table3[[#This Row],[month]]="?","sep",Table3[[#This Row],[month]]) -> Aug | K26: =IF(Table3[[#This Row],[year]]="?","1983",Table3[[#This Row],[year]]) -> 2001 | L26: =IF(Table3[[#This Row],[Hospital tier]]="?","tier - 2",Table3[[#This Row],[Hospital tier]]) -> tier - 3 | M26: =IF(Table3[[#This Row],[City tier]]="?","tier - 2",Table3[[#This Row],[City tier]]) -> tier - 2 | N26: =IF(Table3[[#This Row],[State ID]]="?","unknown",Table3[[#This Row],[State ID]]) -> R1013 | O26: =CONCATENATE(Table3[[#This Row],[date]],"-",Table3[[#This Row],[month2]],"-",Table3[[#This Row],[year2]]) -> 19-Aug-2001 | P26: =DATEDIF(Table3[[#This Row],[date of birth]],DATE(2023,6,8),"y") -> 21 | Q26: 964.71
A27: Id2360 | B27: 1994 | C27: Nov | D27: 22 | E27: 0 | F27: 1006.65 | G27: tier - 3 | H27: tier - 2 | I27: R1013 | J27: =IF(Table3[[#This Row],[month]]="?","sep",Table3[[#This Row],[month]]) -> Nov | K27: =IF(Table3[[#This Row],[year]]="?","1983",Table3[[#This Row],[year]]) -> 1994 | L27: =IF(Table3[[#This Row],[Hospital tier]]="?","tier - 2",Table3[[#This Row],[Hospital tier]]) -> tier - 3 | M27: =IF(Table3[[#This Row],[City tier]]="?","tier - 2",Table3[[#This Row],[City tier]]) -> tier - 2 | N27: =IF(Table3[[#This Row],[State ID]]="?","unknown",Table3[[#This Row],[State ID]]) -> R1013 | O27: =CONCATENATE(Table3[[#This Row],[date]],"-",Table3[[#This Row],[month2]],"-",Table3[[#This Row],[year2]]) -> 22-Nov-1994 | P27: =DATEDIF(Table3[[#This Row],[date of birth]],DATE(2023,6,8),"y") -> 28 | Q27: 1006.65 | S27: Mode of city tier
A28: Id2361 | B28: 2000 | C28: Oct | D28: 9 | E28: 0 | F28: 1012 | G28: tier - 3 | H28: tier - 2 | I28: R1013 | J28: =IF(Table3[[#This Row],[month]]="?","sep",Table3[[#This Row],[month]]) -> Oct | K28: =IF(Table3[[#This Row],[year]]="?","1983",Table3[[#This Row],[year]]) -> 2000 | L28: =IF(Table3[[#This Row],[Hospital tier]]="?","tier - 2",Table3[[#This Row],[Hospital tier]]) -> tier - 3 | M28: =IF(Table3[[#This Row],[City tier]]="?","tier - 2",Table3[[#This Row],[City tier]]) -> tier - 2 | N28: =IF(Table3[[#This Row],[State ID]]="?","unknown",Table3[[#This Row],[State ID]]) -> R1013 | O28: =CONCATENATE(Table3[[#This Row],[date]],"-",Table3[[#This Row],[month2]],"-",Table3[[#This Row],[year2]]) -> 9-Oct-2000 | P28: =DATEDIF(Table3[[#This Row],[date of birth]],DATE(2023,6,8),"y") -> 22 | Q28: 1012 | S28: Row Labels | T28: Count of City tier
A29: Id2362 | B29: 1999 | C29: Aug | D29: 5 | E29: 0 | F29: 1019 | G29: tier - 3 | H29: tier - 2 | I29: R1013 | J29: =IF(Table3[[#This Row],[month]]="?","sep",Table3[[#This Row],[month]]) -> Aug | K29: =IF(Table3[[#This Row],[year]]="?","1983",Table3[[#This Row],[year]]) -> 1999 | L29: =IF(Table3[[#This Row],[Hospital tier]]="?","tier - 2",Table3[[#This Row],[Hospital tier]]) -> tier - 3 | M29: =IF(Table3[[#This Row],[City tier]]="?","tier - 2",Table3[[#This Row],[City tier]]) -> tier - 2 | N29: =IF(Table3[[#This Row],[State ID]]="?","unknown",Table3[[#This Row],[State ID]]) -> R1013 | O29: =CONCATENATE(Table3[[#This Row],[date]],"-",Table3[[#This Row],[month2]],"-",Table3[[#This Row],[year2]]) -> 5-Aug-1999 | P29: =DATEDIF(Table3[[#This Row],[date of birth]],DATE(2023,6,8),"y") -> 23 | Q29: 1019 | S29: ? | T29: 1
A30: Id2363 | B30: 1995 | C30: Oct | D30: 5 | E30: 0 | F30: 1033.74 | G30: tier - 3 | H30: tier - 1 | I30: R1013 | J30: =IF(Table3[[#This Row],[month]]="?","sep",Table3[[#This Row],[month]]) -> Oct | K30: =IF(Table3[[#This Row],[year]]="?","1983",Table3[[#This Row],[year]]) -> 1995 | L30: =IF(Table3[[#This Row],[Hospital tier]]="?","tier - 2",Table3[[#This Row],[Hospital tier]]) -> tier - 3 | M30: =IF(Table3[[#This Row],[City tier]]="?","tier - 2",Table3[[#This Row],[City tier]]) -> tier - 1 | N30: =IF(Table3[[#This Row],[State ID]]="?","unknown",Table3[[#This Row],[State ID]]) -> R1013 | O30: =CONCATENATE(Table3[[#This Row],[date]],"-",Table3[[#This Row],[month2]],"-",Table3[[#This Row],[year2]]) -> 5-Oct-1995 | P30: =DATEDIF(Table3[[#This Row],[date of birth]],DATE(2023,6,8),"y") -> 27 | Q30: 1033.74 | S30: tier - 1 | T30: 734
A31: Id2364 | B31: 1994 | C31: Nov | D31: 17 | E31: 0 | F31: 1044 | G31: tier - 3 | H31: tier - 2 | I31: R1013 | J31: =IF(Table3[[#This Row],[month]]="?","sep",Table3[[#This Row],[month]]) -> Nov | K31: =IF(Table3[[#This Row],[year]]="?","1983",Table3[[#This Row],[year]]) -> 1994 | L31: =IF(Table3[[#This Row],[Hospital tier]]="?","tier - 2",Table3[[#This Row],[Hospital tier]]) -> tier - 3 | M31: =IF(Table3[[#This Row],[City tier]]="?","tier - 2",Table3[[#This Row],[City tier]]) -> tier - 2 | N31: =IF(Table3[[#This Row],[State ID]]="?","unknown",Table3[[#This Row],[State ID]]) -> R1013 | O31: =CONCATENATE(Table3[[#This Row],[date]],"-",Table3[[#This Row],[month2]],"-",Table3[[#This Row],[year2]]) -> 17-Nov-1994 | P31: =DATEDIF(Table3[[#This Row],[date of birth]],DATE(2023,6,8),"y") -> 28 | Q31: 1044 | S31: tier - 2 | T31: 812
A32: Id2365 | B32: 2002 | C32: Jul | D32: 20 | E32: 0 | F32: 1047 | G32: tier - 3 | H32: tier - 1 | I32: R1013 | J32: =IF(Table3[[#This Row],[month]]="?","sep",Table3[[#This Row],[month]]) -> Jul | K32: =IF(Table3[[#This Row],[year]]="?","1983",Table3[[#This Row],[year]]) -> 2002 | L32: =IF(Table3[[#This Row],[Hospital tier]]="?","tier - 2",Table3[[#This Row],[Hospital tier]]) -> tier - 3 | M32: =IF(Table3[[#This Row],[City tier]]="?","tier - 2",Table3[[#This Row],[City tier]]) -> tier - 1 | N32: =IF(Table3[[#This Row],[State ID]]="?","unknown",Table3[[#This Row],[State ID]]) -> R1013 | O32: =CONCATENATE(Table3[[#This Row],[date]],"-",Table3[[#This Row],[month2]],"-",Table3[[#This Row],[year2]]) -> 20-Jul-2002 | P32: =DATEDIF(Table3[[#This Row],[date of birth]],DATE(2023,6,8),"y") -> 20 | Q32: 1047 | S32: tier - 3 | T32: 796
A33: Id2366 | B33: 2002 | C33: Jul | D33: 1 | E33: 0 | F33: 1049 | G33: tier - 3 | H33: tier - 2 | I33: R1012 | J33: =IF(Table3[[#This Row],[month]]="?","sep",Table3[[#This Row],[month]]) -> Jul | K33: =IF(Table3[[#This Row],[year]]="?","1983",Table3[[#This Row],[year]]) -> 2002 | L33: =IF(Table3[[#This Row],[Hospital tier]]="?","tier - 2",Table3[[#This Row],[Hospital tier]]) -> tier - 3 | M33: =IF(Table3[[#This Row],[City tier]]="?","tier - 2",Table3[[#This Row],[City tier]]) -> tier - 2 | N33: =IF(Table3[[#This Row],[State ID]]="?","unknown",Table3[[#This Row],[State ID]]) -> R1012 | O33: =CONCATENATE(Table3[[#This Row],[date]],"-",Table3[[#This Row],[month2]],"-",Table3[[#This Row],[year2]]) -> 1-Jul-2002 | P33: =DATEDIF(Table3[[#This Row],[date of birth]],DATE(2023,6,8),"y") -> 20 | Q33: 1049 | S33: Grand Total | T33: 2343
A34: Id2367 | B34: 1995 | C34: Jun | D34: 1 | E34: 0 | F34: 1056 | G34: tier - 3 | H34: tier - 2 | I34: R1013 | J34: =IF(Table3[[#This Row],[month]]="?","sep",Table3[[#This Row],[month]]) -> Jun | K34: =IF(Table3[[#This Row],[year]]="?","1983",Table3[[#This Row],[year]]) -> 1995 | L34: =IF(Table3[[#This Row],[Hospital tier]]="?","tier - 2",Table3[[#This Row],[Hospital tier]]) -> tier - 3 | M34: =IF(Table3[[#This Row],[City tier]]="?","tier - 2",Table3[[#This Row],[City tier]]) -> tier - 2 | N34: =IF(Table3[[#This Row],[State ID]]="?","unknown",Table3[[#This Row],[State ID]]) -> R1013 | O34: =CONCATENATE(Table3[[#This Row],[date]],"-",Table3[[#This Row],[month2]],"-",Table3[[#This Row],[year2]]) -> 1-Jun-1995 | P34: =DATEDIF(Table3[[#This Row],[date of birth]],DATE(2023,6,8),"y") -> 28 | Q34: 1056
A35: Id2368 | B35: 1993 | C35: Sep | D35: 28 | E35: 0 | F35: 1068 | G35: tier - 3 | H35: tier - 1 | I35: R1013 | J35: =IF(Table3[[#This Row],[month]]="?","sep",Table3[[#This Row],[month]]) -> Sep | K35: =IF(Table3[[#This Row],[year]]="?","1983",Table3[[#This Row],[year]]) -> 1993 | L35: =IF(Table3[[#This Row],[Hospital tier]]="?","tier - 2",Table3[[#This Row],[Hospital tier]]) -> tier - 3 | M35: =IF(Table3[[#This Row],[City tier]]="?","tier - 2",Table3[[#This Row],[City tier]]) -> tier - 1 | N35: =IF(Table3[[#This Row],[State ID]]="?","unknown",Table3[[#This Row],[State ID]]) -> R1013 | O35: =CONCATENATE(Table3[[#This Row],[date]],"-",Table3[[#This Row],[month2]],"-",Table3[[#This Row],[year2]]) -> 28-Sep-1993 | P35: =DATEDIF(Table3[[#This Row],[date of birth]],DATE(2023,6,8),"y") -> 29 | Q35: 1068
A36: Id2369 | B36: 2004 | C36: Aug | D36: 24 | E36: 0 | F36: 1070 | G36: tier - 3 | H36: tier - 3 | I36: R1013 | J36: =IF(Table3[[#This Row],[month]]="?","sep",Table3[[#This Row],[month]]) -> Aug | K36: =IF(Table3[[#This Row],[year]]="?","1983",Table3[[#This Row],[year]]) -> 2004 | L36: =IF(Table3[[#This Row],[Hospital tier]]="?","tier - 2",Table3[[#This Row],[Hospital tier]]) -> tier - 3 | M36: =IF(Table3[[#This Row],[City tier]]="?","tier - 2",Table3[[#This Row],[City tier]]) -> tier - 3 | N36: =IF(Table3[[#This Row],[State ID]]="?","unknown",Table3[[#This Row],[State ID]]) -> R1013 | O36: =CONCATENATE(Table3[[#This Row],[date]],"-",Table3[[#This Row],[month2]],"-",Table3[[#This Row],[year2]]) -> 24-Aug-2004 | P36: =DATEDIF(Table3[[#This Row],[date of birth]],DATE(2023,6,8),"y") -> 18 | Q36: 1070
A37: Id2370 | B37: 1997 | C37: Aug | D37: 13 | E37: 0 | F37: 1071 | G37: tier - 3 | H37: tier - 3 | I37: R1013 | J37: =IF(Table3[[#This Row],[month]]="?","sep",Table3[[#This Row],[month]]) -> Aug | K37: =IF(Table3[[#This Row],[year]]="?","1983",Table3[[#This Row],[year]]) -> 1997 | L37: =IF(Table3[[#This Row],[Hospital tier]]="?","tier - 2",Table3[[#This Row],[Hospital tier]]) -> tier - 3 | M37: =IF(Table3[[#This Row],[City tier]]="?","tier - 2",Table3[[#This Row],[City tier]]) -> tier - 3 | N37: =IF(Table3[[#This Row],[State ID]]="?","unknown",Table3[[#This Row],[State ID]]) -> R1013 | O37: =CONCATENATE(Table3[[#This Row],[date]],"-",Table3[[#This Row],[month2]],"-",Table3[[#This Row],[year2]]) -> 13-Aug-1997 | P37: =DATEDIF(Table3[[#This Row],[date of birth]],DATE(2023,6,8),"y") -> 25 | Q37: 1071
A38: Id2371 | B38: 1998 | C38: Dec | D38: 26 | E38: 0 | F38: 1082 | G38: tier - 3 | H38: tier - 2 | I38: R1013 | J38: =IF(Table3[[#This Row],[month]]="?","sep",Table3[[#This Row],[month]]) -> Dec | K38: =IF(Table3[[#This Row],[year]]="?","1983",Table3[[#This Row],[year]]) -> 1998 | L38: =IF(Table3[[#This Row],[Hospital tier]]="?","tier - 2",Table3[[#This Row],[Hospital tier]]) -> tier - 3 | M38: =IF(Table3[[#This Row],[City tier]]="?","tier - 2",Table3[[#This Row],[City tier]]) -> tier - 2 | N38: =IF(Table3[[#This Row],[State ID]]="?","unknown",Table3[[#This Row],[State ID]]) -> R1013 | O38: =CONCATENATE(Table3[[#This Row],[date]],"-",Table3[[#This Row],[month2]],"-",Table3[[#This Row],[year2]]) -> 26-Dec-1998 | P38: =DATEDIF(Table3[[#This Row],[date of birth]],DATE(2023,6,8),"y") -> 24 | Q38: 1082
A39: Id2372 | B39: 2002 | C39: Aug | D39: 13 | E39: 0 | F39: 1086 | G39: tier - 3 | H39: tier - 3 | I39: R1013 | J39: =IF(Table3[[#This Row],[month]]="?","sep",Table3[[#This Row],[month]]) -> Aug | K39: =IF(Table3[[#This Row],[year]]="?","1983",Table3[[#This Row],[year]]) -> 2002 | L39: =IF(Table3[[#This Row],[Hospital tier]]="?","tier - 2",Table3[[#This Row],[Hospital tier]]) -> tier - 3 | M39: =IF(Table3[[#This Row],[City tier]]="?","tier - 2",Table3[[#This Row],[City tier]]) -> tier - 3 | N39: =IF(Table3[[#This Row],[State ID]]="?","unknown",Table3[[#This Row],[State ID]]) -> R1013 | O39: =CONCATENATE(Table3[[#This Row],[date]],"-",Table3[[#This Row],[month2]],"-",Table3[[#This Row],[year2]]) -> 13-Aug-2002 | P39: =DATEDIF(Table3[[#This Row],[date of birth]],DATE(2023,6,8),"y") -> 20 | Q39: 1086
A40: Id2373 | B40: 2004 | C40: Nov | D40: 12 | E40: 0 | F40: 1121.87 | G40: tier - 3 | H40: tier - 1 | I40: R1013 | J40: =IF(Table3[[#This Row],[month]]="?","sep",Table3[[#This Row],[month]]) -> Nov | K40: =IF(Table3[[#This Row],[year]]="?","1983",Table3[[#This Row],[year]]) -> 2004 | L40: =IF(Table3[[#This Row],[Hospital tier]]="?","tier - 2",Table3[[#This Row],[Hospital tier]]) -> tier - 3 | M40: =IF(Table3[[#This Row],[City tier]]="?","tier - 2",Table3[[#This Row],[City tier]]) -> tier - 1 | N40: =IF(Table3[[#This Row],[State ID]]="?","unknown",Table3[[#This Row],[State ID]]) -> R1013 | O40: =CONCATENATE(Table3[[#This Row],[date]],"-",Table3[[#This Row],[month2]],"-",Table3[[#This Row],[year2]]) -> 12-Nov-2004 | P40: =DATEDIF(Table3[[#This Row],[date of birth]],DATE(2023,6,8),"y") -> 18 | Q40: 1121.87
...

Sheet healthcare
A1: =VLOOKUP('Customer Names'!A1,'Customer Names'!A1:A2336,1,FALSE) -> Customer ID | B1: =VLOOKUP(Table6[[#Headers],[NAME]],'Customer Names'!G:G,1,FALSE) -> NAME | C1: =VLOOKUP(Table4[[#Headers],[BMI]],Table4[[#All],[BMI]],1,FALSE) -> BMI | D1: =VLOOKUP(Table4[[#Headers],[HBA1C]],Table4[[#All],[HBA1C]],1,FALSE) -> HBA1C | E1: =VLOOKUP(Table4[[#Headers],[Any Transplants]],Table4[[#All],[Any Transplants]],1,FALSE) -> Any Transplants | F1: =VLOOKUP(Table4[[#Headers],[Cancer history]],Table4[[#All],[Cancer history]],1,FALSE) -> Cancer history | G1: =VLOOKUP(Table4[[#Headers],[Smoker2]],Table4[[#All],[Smoker2]],1,FALSE) -> Smoker2 | H1: =VLOOKUP(Table4[[#Headers],[Heart Issues]],Table4[[#All],[Heart Issues]],1,FALSE) -> Heart Issues | I1: =VLOOKUP(Table4[[#Headers],[Number of Major Surgeries]],Table4[[#All],[Number of Major Surgeries]],1,FALSE) -> Number of Major Surgeries | J1: =VLOOKUP('Medical Examinations'!M1,'Medical Examinations'!M1:M2336,1,FALSE) -> Weight Status | K1: =VLOOKUP('Medical Examinations'!N1,'Medical Examinations'!N1:N2336,1,FALSE) -> diebetes | L1: =VLOOKUP(Table3[[#Headers],[date of birth]],Table3[[#All],[date of birth]],1,FALSE) -> date of birth | M1: =VLOOKUP(Table3[[#Headers],[age]],Table3[[#All],[age]],1,FALSE) -> age | N1: =VLOOKUP(Table3[[#Headers],[charges2]],Table3[[#All],[charges2]],1,FALSE) -> charges2 | O1: =VLOOKUP(Table3[[#Headers],[HOSPITAL TIER2]],Table3[[#All],[HOSPITAL TIER2]],1,FALSE) -> HOSPITAL TIER2 | P1: =VLOOKUP(Table3[[#Headers],[city tier2]],Table3[[#All],[city tier2]],1,FALSE) -> city tier2 | Q1: =VLOOKUP(Table3[[#Headers],[state id2]],Table3[[#All],[state id2]],1,FALSE) -> state id2 | R1: CORRELATION OF AGE AND BMI | S1: CORRELATION OF AGE AND HBA1C
